Workbook

Sheet README
A1: SAEIS | دليل النموذج المالي ولوحة Power BI
A2: نسخة محدثة مبنية على ملف SAEISSmartAuditPitchDeck-Updated.pdf
A4: الغرض | B4: نموذج تخطيطي قابل للتحرير لتحليل الميزانية، الإيرادات، الأرباح، الانحرافات، نقطة التعادل، وفترة الاسترداد والتدفق التشغيلي التراكمي.
A5: البيانات المؤكدة من العرض | B5: أسعار الباقات السنوية: 2,500 دولار للباقة الأساسية، 7,500 دولار للباقة الاحترافية، وباقة المؤسسات حسب المتطلبات. كما يذكر العرض أهداف أثر بنسبة 90% لدقة اكتشاف الأخطاء و60% لتقليل وقت التدقيق.
A6: البيانات القابلة للتحرير | B6: عدد العملاء، سرعة اكتساب العملاء، التكلفة المتغيرة، التكاليف الثابتة، المصروفات الفعلية، وتوزيع الميزانية. القيم الافتراضية في Inputs سيناريو تخطيطي وليست نتائج محققة.
A7: طريقة الاستخدام | B7: عدّل الخلايا الزرقاء في Inputs وActuals_Monthly وBudget_Variance، ثم افتح PowerBI_Export في Power BI أو انسخه إلى نموذج البيانات.
A8: تعريف نقطة التعادل | B8: نقطة التعادل الشهرية = التكاليف الثابتة الشهرية ÷ هامش المساهمة. عدد العملاء المكافئ = نقطة التعادل الشهرية ÷ متوسط الإيراد الشهري للعميل.
A9: تعريف فترة الاسترداد | B9: عدد الأشهر حتى يغطي التدفق التشغيلي التراكمي مبلغ التمويل الأولي. لا يعامل التمويل كمصروف تشغيلي داخل منحنى التدفق.
A10: ملاحظة مهمة | B10: لا تمثل القيم الافتراضية توقعًا ماليًا نهائيًا. تكلفة 2,625 دولار الشهرية هدف تخطيطي يجب التحقق منه بعقود وتكاليف فعلية قبل مشاركة النتائج مع الممولين.

Sheet Inputs
A1: SAEIS | الافتراضات والمدخلات
A2: الخلايا الزرقاء قابلة للتعديل. المصادر المعلّمة من العرض، بينما الافتراضات التشغيلية تحتاج إلى تحقق من الفريق.
A4: الفئة | B4: المتغير | C4: القيمة | D4: الوحدة | E4: الحالة | F4: المصدر أو الملاحظة
A5: تمويل | B5: طلب التمويل | C5: 26500 | D5: دولار | E5: مدخل من سياق المشروع | F5: مبلغ طلب التمويل المذكور سابقًا في العرض.
A6: التسعير | B6: الباقة الأساسية سنويًا | C6: 2500 | D6: دولار | E6: من العرض | F6: المنشآت الصغيرة.
A7: التسعير | B7: الباقة الاحترافية سنويًا | C7: 7500 | D7: دولار | E7: من العرض | F7: الشركات المتوسطة.
A8: التسعير | B8: باقة المؤسسات سنويًا | C8: 0 | D8: دولار | E8: يحتاج إدخالًا | F8: السعر حسب المتطلبات، لذلك يترك صفرًا حتى يحدد الفريق السعر.
A9: العملاء | B9: عملاء أساسيون عند البداية | C9: 0 | D9: عميل | E9: افتراض تخطيطي | F9: عدّل حسب العملاء الحاليين أو التجارب المتوقعة.
A10: العملاء | B10: عملاء احترافيون عند البداية | C10: 0 | D10: عميل | E10: افتراض تخطيطي | F10: عدّل حسب العملاء الحاليين أو التجارب المتوقعة.
A11: العملاء | B11: عملاء مؤسسات عند البداية | C11: 0 | D11: عميل | E11: افتراض تخطيطي | F11: اتركه صفرًا حتى تتوافر عقود المؤسسات.
A12: النمو | B12: عملاء أساسيون جدد شهريًا | C12: 0.5 | D12: عميل/شهر | E12: افتراض تخطيطي | F12: قابل للتغيير إلى خطة المبيعات الواقعية.
A13: النمو | B13: عملاء احترافيون جدد شهريًا | C13: 0.25 | D13: عميل/شهر | E13: افتراض تخطيطي | F13: قابل للتغيير إلى خطة المبيعات الواقعية.
A14: النمو | B14: عملاء مؤسسات جدد شهريًا | C14: 0 | D14: عميل/شهر | E14: افتراض تخطيطي | F14: يتطلب سعرًا سنويًا مدخلًا.
A15: التكلفة | B15: معدل الانسحاب الشهري | C15: 0 | D15: % | E15: افتراض تخطيطي | F15: عدّل بعد توفر بيانات الاحتفاظ.
A16: التكلفة | B16: التكلفة المتغيرة كنسبة من الإيراد | C16: 0.2 | D16: % | E16: افتراض تخطيطي | F16: تستخدم لحساب هامش المساهمة.
... A20: الأثر | B20: هدف خفض وقت التدقيق | C20: 0.6 | D20: % | E20: هدف من العرض | F20: يعرض كهدف أداء وليس نتيجة فعلية.
A21: معايرة نقطة التعادل | B21: إيراد الشهر 12 المرجعي | C21: =Monthly_Model!J16 -> 3125 | D21: دولار | E21: صيغة تحقق | F21: يرتبط مباشرة بالنموذج الشهري لتوثيق افتراضات نقطة التعادل.
A22: معايرة نقطة التعادل | B22: هامش المساهمة المرجعي | C22: =Monthly_Model!O16 -> 0.8 | D22: % | E22: صيغة تحقق | F22: يرتبط مباشرة بالنموذج الشهري لتوثيق افتراضات نقطة التعادل.
A23: معايرة نقطة التعادل | B23: الربح التشغيلي المرجعي – شهر 12 | C23: =Monthly_Model!M16 -> -125 | D23: دولار | E23: صيغة تحقق | F23: يرتبط مباشرة بالنموذج الشهري لتوثيق افتراضات نقطة التعادل.
A24: معايرة نقطة التعادل | B24: نقطة التعادل الشهرية – تحقق | C24: =IFERROR(C17/C22,"") -> 3281.25 | D24: دولار | E24: صيغة تحقق | F24: يرتبط مباشرة بالنموذج الشهري لتوثيق افتراضات نقطة التعادل.

Sheet Budget_Variance
A1: SAEIS | الميزانية والانحرافات
A2: أدخل المصروف الفعلي في الخلايا الزرقاء. الانحراف الإيجابي في المصروفات يعني تجاوز الميزانية.
A4: البند | B4: الميزانية المخططة | C4: الفعلي | D4: الانحراف | E4: الانحراف % | F4: الحالة | G4: المخرج المرتبط
A5: بناء المنتج والنسخة التجريبية | B5: 11925 | D5: =IF(C5="","",C5-B5) | E5: =IF(C5="","",IF(B5=0,"",D5/B5)) | F5: =IF(C5="","أدخل الفعلي",IF(D5>0,"تجاوز",IF(D5<0,"أقل من الميزانية","مطابق"))) -> أدخل الفعلي | G5: MVP قابل للتشغيل
A6: التكامل والأمان والامتثال التقني | B6: 6625 | D6: =IF(C6="","",C6-B6) | E6: =IF(C6="","",IF(B6=0,"",D6/B6)) | F6: =IF(C6="","أدخل الفعلي",IF(D6>0,"تجاوز",IF(D6<0,"أقل من الميزانية","مطابق"))) -> أدخل الفعلي | G6: موصل ERP وبيئة تجربة آمنة
A7: إثبات السوق وتجربة العملاء | B7: 5300 | D7: =IF(C7="","",C7-B7) | E7: =IF(C7="","",IF(B7=0,"",D7/B7)) | F7: =IF(C7="","أدخل الفعلي",IF(D7>0,"تجاوز",IF(D7<0,"أقل من الميزانية","مطابق"))) -> أدخل الفعلي | G7: تجارب عميل ودراسة حالة
A8: التشغيل والامتثال الإداري | B8: 2650 | D8: =IF(C8="","",C8-B8) | E8: =IF(C8="","",IF(B8=0,"",D8/B8)) | F8: =IF(C8="","أدخل الفعلي",IF(D8>0,"تجاوز",IF(D8<0,"أقل من الميزانية","مطابق"))) -> أدخل الفعلي | G8: جاهزية تشغيلية وقانونية
A10: الإجمالي | B10: =SUM(B5:B8) -> 26500 | C10: =IF(COUNTA(C5:C8)=0,"",SUM(C5:C8)) | D10: =IF(C10="","",C10-B10) | E10: =IF(C10="","",D10/B10) | F10: =IF(C10="","أدخل الفعلي",IF(D10>0,"تجاوز",IF(D10<0,"أقل من الميزانية","مطابق"))) -> أدخل الفعلي

Sheet Actuals_Monthly
A1: SAEIS | المدخلات الفعلية الشهرية
A2: أدخل القيم الفعلية المتاحة. الخلايا الفارغة لا تُعامل كصفر داخل مقارنة الأداء.
A4: الشهر | B4: الإيراد الفعلي | C4: التكلفة المتغيرة الفعلية | D4: التكاليف الثابتة الفعلية | E4: مصروفات أخرى فعلية | F4: ملاحظات
A5: 1 | F5: أدخل البيانات الفعلية عند توفرها
A6: 2 | F6: أدخل البيانات الفعلية عند توفرها
A7: 3 | F7: أدخل البيانات الفعلية عند توفرها
A8: 4 | F8: أدخل البيانات الفعلية عند توفرها
A9: 5 | F9: أدخل البيانات الفعلية عند توفرها
A10: 6 | F10: أدخل البيانات الفعلية عند توفرها
A11: 7 | F11: أدخل البيانات الفعلية عند توفرها
A12: 8 | F12: أدخل البيانات الفعلية عند توفرها
A13: 9 | F13: أدخل البيانات الفعلية عند توفرها
A14: 10 | F14: أدخل البيانات الفعلية عند توفرها
A15: 11 | F15: أدخل البيانات الفعلية عند توفرها
A16: 12 | F16: أدخل البيانات الفعلية عند توفرها
... A28: 24 | F28: أدخل البيانات الفعلية عند توفرها

Sheet Monthly_Model
A1: SAEIS | النموذج التشغيلي الشهري
A2: الجزء الأخضر يمثل الخطة/السيناريو، والجزء الأزرق يُسحب من Actuals_Monthly عند إدخال الفعلي.
A4: الشهر | B4: الربع | C4: عملاء أساسيون | D4: عملاء احترافيون | E4: عملاء مؤسسات | F4: إجمالي العملاء | G4: إيراد أساسي | H4: إيراد احترافي | I4: إيراد مؤسسات | J4: إجمالي الإيراد المخطط | K4: التكلفة المتغيرة المخططة | L4: التكاليف الثابتة المخططة | M4: الربح التشغيلي المخطط | N4: التدفق التشغيلي التراكمي المخطط | O4: هامش المساهمة | P4: الإيراد الفعلي | Q4: الربح الفعلي | R4: انحراف الإيراد | S4: انحراف الربح | T4: حالة الفعلي | U4: Payback Flag
A5: 1 | B5: ="Q"&ROUNDUP(A5/3,0) -> Q1 | C5: =Inputs!$C$9*(1-Inputs!$C$15)+Inputs!$C$12 -> 0.5 | D5: =Inputs!$C$10*(1-Inputs!$C$15)+Inputs!$C$13 -> 0.25 | E5: =Inputs!$C$11*(1-Inputs!$C$15)+Inputs!$C$14 -> 0 | F5: =SUM(C5:E5) -> 0.75 | G5: =C5*Inputs!$C$6/12 -> 104.16667 | H5: =D5*Inputs!$C$7/12 -> 156.25 | I5: =E5*Inputs!$C$8/12 -> 0 | J5: =SUM(G5:I5) -> 260.41667 | K5: =J5*Inputs!$C$16 -> 52.083333 | L5: =Inputs!$C$17 -> 2625 | M5: =J5-K5-L5 -> -2416.6667 | N5: =M5 -> -2416.6667 | O5: =IF(J5=0,"",(J5-K5)/J5) -> 0.8 | P5: =IF(Actuals_Monthly!B5="","",Actuals_Monthly!B5) | Q5: =IF(OR(Actuals_Monthly!B5="",Actuals_Monthly!C5="",Actuals_Monthly!D5=""),"",Actuals_Monthly!B5-Actuals_Monthly!C5-Actuals_Monthly!D5) | R5: =IF(P5="","",P5-J5) | S5: =IF(Q5="","",Q5-M5) | T5: =IF(P5="","أدخل الفعلي",IF(R5>=0,"فوق الخطة","دون الخطة")) -> أدخل الفعلي | U5: =IF(N5>=Inputs!$C$5,1,0) -> 0
A6: 2 | B6: ="Q"&ROUNDUP(A6/3,0) -> Q1 | C6: =C5*(1-Inputs!$C$15)+Inputs!$C$12 -> 1 | D6: =D5*(1-Inputs!$C$15)+Inputs!$C$13 -> 0.5 | E6: =E5*(1-Inputs!$C$15)+Inputs!$C$14 -> 0 | F6: =SUM(C6:E6) -> 1.5 | G6: =C6*Inputs!$C$6/12 -> 208.33333 | H6: =D6*Inputs!$C$7/12 -> 312.5 | I6: =E6*Inputs!$C$8/12 -> 0 | J6: =SUM(G6:I6) -> 520.83333 | K6: =J6*Inputs!$C$16 -> 104.16667 | L6: =Inputs!$C$17 -> 2625 | M6: =J6-K6-L6 -> -2208.3333 | N6: =N5+M6 -> -4625 | O6: =IF(J6=0,"",(J6-K6)/J6) -> 0.8 | P6: =IF(Actuals_Monthly!B6="","",Actuals_Monthly!B6) | Q6: =IF(OR(Actuals_Monthly!B6="",Actuals_Monthly!C6="",Actuals_Monthly!D6=""),"",Actuals_Monthly!B6-Actuals_Monthly!C6-Actuals_Monthly!D6) | R6: =IF(P6="","",P6-J6) | S6: =IF(Q6="","",Q6-M6) | T6: =IF(P6="","أدخل الفعلي",IF(R6>=0,"فوق الخطة","دون الخطة")) -> أدخل الفعلي | U6: =IF(N6>=Inputs!$C$5,1,0) -> 0
A7: 3 | B7: ="Q"&ROUNDUP(A7/3,0) -> Q1 | C7: =C6*(1-Inputs!$C$15)+Inputs!$C$12 -> 1.5 | D7: =D6*(1-Inputs!$C$15)+Inputs!$C$13 -> 0.75 | E7: =E6*(1-Inputs!$C$15)+Inputs!$C$14 -> 0 | F7: =SUM(C7:E7) -> 2.25 | G7: =C7*Inputs!$C$6/12 -> 312.5 | H7: =D7*Inputs!$C$7/12 -> 468.75 | I7: =E7*Inputs!$C$8/12 -> 0 | J7: =SUM(G7:I7) -> 781.25 | K7: =J7*Inputs!$C$16 -> 156.25 | L7: =Inputs!$C$17 -> 2625 | M7: =J7-K7-L7 -> -2000 | N7: =N6+M7 -> -6625 | O7: =IF(J7=0,"",(J7-K7)/J7) -> 0.8 | P7: =IF(Actuals_Monthly!B7="","",Actuals_Monthly!B7) | Q7: =IF(OR(Actuals_Monthly!B7="",Actuals_Monthly!C7="",Actuals_Monthly!D7=""),"",Actuals_Monthly!B7-Actuals_Monthly!C7-Actuals_Monthly!D7) | R7: =IF(P7="","",P7-J7) | S7: =IF(Q7="","",Q7-M7) | T7: =IF(P7="","أدخل الفعلي",IF(R7>=0,"فوق الخطة","دون الخطة")) -> أدخل الفعلي | U7: =IF(N7>=Inputs!$C$5,1,0) -> 0
A8: 4 | B8: ="Q"&ROUNDUP(A8/3,0) -> Q2 | C8: =C7*(1-Inputs!$C$15)+Inputs!$C$12 -> 2 | D8: =D7*(1-Inputs!$C$15)+Inputs!$C$13 -> 1 | E8: =E7*(1-Inputs!$C$15)+Inputs!$C$14 -> 0 | F8: =SUM(C8:E8) -> 3 | G8: =C8*Inputs!$C$6/12 -> 416.66667 | H8: =D8*Inputs!$C$7/12 -> 625 | I8: =E8*Inputs!$C$8/12 -> 0 | J8: =SUM(G8:I8) -> 1041.6667 | K8: =J8*Inputs!$C$16 -> 208.33333 | L8: =Inputs!$C$17 -> 2625 | M8: =J8-K8-L8 -> -1791.6667 | N8: =N7+M8 -> -8416.6667 | O8: =IF(J8=0,"",(J8-K8)/J8) -> 0.8 | P8: =IF(Actuals_Monthly!B8="","",Actuals_Monthly!B8) | Q8: =IF(OR(Actuals_Monthly!B8="",Actuals_Monthly!C8="",Actuals_Monthly!D8=""),"",Actuals_Monthly!B8-Actuals_Monthly!C8-Actuals_Monthly!D8) | R8: =IF(P8="","",P8-J8) | S8: =IF(Q8="","",Q8-M8) | T8: =IF(P8="","أدخل الفعلي",IF(R8>=0,"فوق الخطة","دون الخطة")) -> أدخل الفعلي | U8: =IF(N8>=Inputs!$C$5,1,0) -> 0
A9: 5 | B9: ="Q"&ROUNDUP(A9/3,0) -> Q2 | C9: =C8*(1-Inputs!$C$15)+Inputs!$C$12 -> 2.5 | D9: =D8*(1-Inputs!$C$15)+Inputs!$C$13 -> 1.25 | E9: =E8*(1-Inputs!$C$15)+Inputs!$C$14 -> 0 | F9: =SUM(C9:E9) -> 3.75 | G9: =C9*Inputs!$C$6/12 -> 520.83333 | H9: =D9*Inputs!$C$7/12 -> 781.25 | I9: =E9*Inputs!$C$8/12 -> 0 | J9: =SUM(G9:I9) -> 1302.0833 | K9: =J9*Inputs!$C$16 -> 260.41667 | L9: =Inputs!$C$17 -> 2625 | M9: =J9-K9-L9 -> -1583.3333 | N9: =N8+M9 -> -10000 | O9: =IF(J9=0,"",(J9-K9)/J9) -> 0.8 | P9: =IF(Actuals_Monthly!B9="","",Actuals_Monthly!B9) | Q9: =IF(OR(Actuals_Monthly!B9="",Actuals_Monthly!C9="",Actuals_Monthly!D9=""),"",Actuals_Monthly!B9-Actuals_Monthly!C9-Actuals_Monthly!D9) | R9: =IF(P9="","",P9-J9) | S9: =IF(Q9="","",Q9-M9) | T9: =IF(P9="","أدخل الفعلي",IF(R9>=0,"فوق الخطة","دون الخطة")) -> أدخل الفعلي | U9: =IF(N9>=Inputs!$C$5,1,0) -> 0
A10: 6 | B10: ="Q"&ROUNDUP(A10/3,0) -> Q2 | C10: =C9*(1-Inputs!$C$15)+Inputs!$C$12 -> 3 | D10: =D9*(1-Inputs!$C$15)+Inputs!$C$13 -> 1.5 | E10: =E9*(1-Inputs!$C$15)+Inputs!$C$14 -> 0 | F10: =SUM(C10:E10) -> 4.5 | G10: =C10*Inputs!$C$6/12 -> 625 | H10: =D10*Inputs!$C$7/12 -> 937.5 | I10: =E10*Inputs!$C$8/12 -> 0 | J10: =SUM(G10:I10) -> 1562.5 | K10: =J10*Inputs!$C$16 -> 312.5 | L10: =Inputs!$C$17 -> 2625 | M10: =J10-K10-L10 -> -1375 | N10: =N9+M10 -> -11375 | O10: =IF(J10=0,"",(J10-K10)/J10) -> 0.8 | P10: =IF(Actuals_Monthly!B10="","",Actuals_Monthly!B10) | Q10: =IF(OR(Actuals_Monthly!B10="",Actuals_Monthly!C10="",Actuals_Monthly!D10=""),"",Actuals_Monthly!B10-Actuals_Monthly!C10-Actuals_Monthly!D10) | R10: =IF(P10="","",P10-J10) | S10: =IF(Q10="","",Q10-M10) | T10: =IF(P10="","أدخل الفعلي",IF(R10>=0,"فوق الخطة","دون الخطة")) -> أدخل الفعلي | U10: =IF(N10>=Inputs!$C$5,1,0) -> 0
A11: 7 | B11: ="Q"&ROUNDUP(A11/3,0) -> Q3 | C11: =C10*(1-Inputs!$C$15)+Inputs!$C$12 -> 3.5 | D11: =D10*(1-Inputs!$C$15)+Inputs!$C$13 -> 1.75 | E11: =E10*(1-Inputs!$C$15)+Inputs!$C$14 -> 0 | F11: =SUM(C11:E11) -> 5.25 | G11: =C11*Inputs!$C$6/12 -> 729.16667 | H11: =D11*Inputs!$C$7/12 -> 1093.75 | I11: =E11*Inputs!$C$8/12 -> 0 | J11: =SUM(G11:I11) -> 1822.9167 | K11: =J11*Inputs!$C$16 -> 364.58333 | L11: =Inputs!$C$17 -> 2625 | M11: =J11-K11-L11 -> -1166.6667 | N11: =N10+M11 -> -12541.667 | O11: =IF(J11=0,"",(J11-K11)/J11) -> 0.8 | P11: =IF(Actuals_Monthly!B11="","",Actuals_Monthly!B11) | Q11: =IF(OR(Actuals_Monthly!B11="",Actuals_Monthly!C11="",Actuals_Monthly!D11=""),"",Actuals_Monthly!B11-Actuals_Monthly!C11-Actuals_Monthly!D11) | R11: =IF(P11="","",P11-J11) | S11: =IF(Q11="","",Q11-M11) | T11: =IF(P11="","أدخل الفعلي",IF(R11>=0,"فوق الخطة","دون الخطة")) -> أدخل الفعلي | U11: =IF(N11>=Inputs!$C$5,1,0) -> 0
A12: 8 | B12: ="Q"&ROUNDUP(A12/3,0) -> Q3 | C12: =C11*(1-Inputs!$C$15)+Inputs!$C$12 -> 4 | D12: =D11*(1-Inputs!$C$15)+Inputs!$C$13 -> 2 | E12: =E11*(1-Inputs!$C$15)+Inputs!$C$14 -> 0 | F12: =SUM(C12:E12) -> 6 | G12: =C12*Inputs!$C$6/12 -> 833.33333 | H12: =D12*Inputs!$C$7/12 -> 1250 | I12: =E12*Inputs!$C$8/12 -> 0 | J12: =SUM(G12:I12) -> 2083.3333 | K12: =J12*Inputs!$C$16 -> 416.66667 | L12: =Inputs!$C$17 -> 2625 | M12: =J12-K12-L12 -> -958.33333 | N12: =N11+M12 -> -13500 | O12: =IF(J12=0,"",(J12-K12)/J12) -> 0.8 | P12: =IF(Actuals_Monthly!B12="","",Actuals_Monthly!B12) | Q12: =IF(OR(Actuals_Monthly!B12="",Actuals_Monthly!C12="",Actuals_Monthly!D12=""),"",Actuals_Monthly!B12-Actuals_Monthly!C12-Actuals_Monthly!D12) | R12: =IF(P12="","",P12-J12) | S12: =IF(Q12="","",Q12-M12) | T12: =IF(P12="","أدخل الفعلي",IF(R12>=0,"فوق الخطة","دون الخطة")) -> أدخل الفعلي | U12: =IF(N12>=Inputs!$C$5,1,0) -> 0
A13: 9 | B13: ="Q"&ROUNDUP(A13/3,0) -> Q3 | C13: =C12*(1-Inputs!$C$15)+Inputs!$C$12 -> 4.5 | D13: =D12*(1-Inputs!$C$15)+Inputs!$C$13 -> 2.25 | E13: =E12*(1-Inputs!$C$15)+Inputs!$C$14 -> 0 | F13: =SUM(C13:E13) -> 6.75 | G13: =C13*Inputs!$C$6/12 -> 937.5 | H13: =D13*Inputs!$C$7/12 -> 1406.25 | I13: =E13*Inputs!$C$8/12 -> 0 | J13: =SUM(G13:I13) -> 2343.75 | K13: =J13*Inputs!$C$16 -> 468.75 | L13: =Inputs!$C$17 -> 2625 | M13: =J13-K13-L13 -> -750 | N13: =N12+M13 -> -14250 | O13: =IF(J13=0,"",(J13-K13)/J13) -> 0.8 | P13: =IF(Actuals_Monthly!B13="","",Actuals_Monthly!B13) | Q13: =IF(OR(Actuals_Monthly!B13="",Actuals_Monthly!C13="",Actuals_Monthly!D13=""),"",Actuals_Monthly!B13-Actuals_Monthly!C13-Actuals_Monthly!D13) | R13: =IF(P13="","",P13-J13) | S13: =IF(Q13="","",Q13-M13) | T13: =IF(P13="","أدخل الفعلي",IF(R13>=0,"فوق الخطة","دون الخطة")) -> أدخل الفعلي | U13: =IF(N13>=Inputs!$C$5,1,0) -> 0
A14: 10 | B14: ="Q"&ROUNDUP(A14/3,0) -> Q4 | C14: =C13*(1-Inputs!$C$15)+Inputs!$C$12 -> 5 | D14: =D13*(1-Inputs!$C$15)+Inputs!$C$13 -> 2.5 | E14: =E13*(1-Inputs!$C$15)+Inputs!$C$14 -> 0 | F14: =SUM(C14:E14) -> 7.5 | G14: =C14*Inputs!$C$6/12 -> 1041.6667 | H14: =D14*Inputs!$C$7/12 -> 1562.5 | I14: =E14*Inputs!$C$8/12 -> 0 | J14: =SUM(G14:I14) -> 2604.1667 | K14: =J14*Inputs!$C$16 -> 520.83333 | L14: =Inputs!$C$17 -> 2625 | M14: =J14-K14-L14 -> -541.66667 | N14: =N13+M14 -> -14791.667 | O14: =IF(J14=0,"",(J14-K14)/J14) -> 0.8 | P14: =IF(Actuals_Monthly!B14="","",Actuals_Monthly!B14) | Q14: =IF(OR(Actuals_Monthly!B14="",Actuals_Monthly!C14="",Actuals_Monthly!D14=""),"",Actuals_Monthly!B14-Actuals_Monthly!C14-Actuals_Monthly!D14) | R14: =IF(P14="","",P14-J14) | S14: =IF(Q14="","",Q14-M14) | T14: =IF(P14="","أدخل الفعلي",IF(R14>=0,"فوق الخطة","دون الخطة")) -> أدخل الفعلي | U14: =IF(N14>=Inputs!$C$5,1,0) -> 0
A15: 11 | B15: ="Q"&ROUNDUP(A15/3,0) -> Q4 | C15: =C14*(1-Inputs!$C$15)+Inputs!$C$12 -> 5.5 | D15: =D14*(1-Inputs!$C$15)+Inputs!$C$13 -> 2.75 | E15: =E14*(1-Inputs!$C$15)+Inputs!$C$14 -> 0 | F15: =SUM(C15:E15) -> 8.25 | G15: =C15*Inputs!$C$6/12 -> 1145.8333 | H15: =D15*Inputs!$C$7/12 -> 1718.75 | I15: =E15*Inputs!$C$8/12 -> 0 | J15: =SUM(G15:I15) -> 2864.5833 | K15: =J15*Inputs!$C$16 -> 572.91667 | L15: =Inputs!$C$17 -> 2625 | M15: =J15-K15-L15 -> -333.33333 | N15: =N14+M15 -> -15125 | O15: =IF(J15=0,"",(J15-K15)/J15) -> 0.8 | P15: =IF(Actuals_Monthly!B15="","",Actuals_Monthly!B15) | Q15: =IF(OR(Actuals_Monthly!B15="",Actuals_Monthly!C15="",Actuals_Monthly!D15=""),"",Actuals_Monthly!B15-Actuals_Monthly!C15-Actuals_Monthly!D15) | R15: =IF(P15="","",P15-J15) | S15: =IF(Q15="","",Q15-M15) | T15: =IF(P15="","أدخل الفعلي",IF(R15>=0,"فوق الخطة","دون الخطة")) -> أدخل الفعلي | U15: =IF(N15>=Inputs!$C$5,1,0) -> 0
A16: 12 | B16: ="Q"&ROUNDUP(A16/3,0) -> Q4 | C16: =C15*(1-Inputs!$C$15)+Inputs!$C$12 -> 6 | D16: =D15*(1-Inputs!$C$15)+Inputs!$C$13 -> 3 | E16: =E15*(1-Inputs!$C$15)+Inputs!$C$14 -> 0 | F16: =SUM(C16:E16) -> 9 | G16: =C16*Inputs!$C$6/12 -> 1250 | H16: =D16*Inputs!$C$7/12 -> 1875 | I16: =E16*Inputs!$C$8/12 -> 0 | J16: =SUM(G16:I16) -> 3125 | K16: =J16*Inputs!$C$16 -> 625 | L16: =Inputs!$C$17 -> 2625 | M16: =J16-K16-L16 -> -125 | N16: =N15+M16 -> -15250 | O16: =IF(J16=0,"",(J16-K16)/J16) -> 0.8 | P16: =IF(Actuals_Monthly!B16="","",Actuals_Monthly!B16) | Q16: =IF(OR(Actuals_Monthly!B16="",Actuals_Monthly!C16="",Actuals_Monthly!D16=""),"",Actuals_Monthly!B16-Actuals_Monthly!C16-Actuals_Monthly!D16) | R16: =IF(P16="","",P16-J16) | S16: =IF(Q16="","",Q16-M16) | T16: =IF(P16="","أدخل الفعلي",IF(R16>=0,"فوق الخطة","دون الخطة")) -> أدخل الفعلي | U16: =IF(N16>=Inputs!$C$5,1,0) -> 0
A17: 13 | B17: ="Q"&ROUNDUP(A17/3,0) -> Q5 | C17: =C16*(1-Inputs!$C$15)+Inputs!$C$12 -> 6.5 | D17: =D16*(1-Inputs!$C$15)+Inputs!$C$13 -> 3.25 | E17: =E16*(1-Inputs!$C$15)+Inputs!$C$14 -> 0 | F17: =SUM(C17:E17) -> 9.75 | G17: =C17*Inputs!$C$6/12 -> 1354.1667 | H17: =D17*Inputs!$C$7/12 -> 2031.25 | I17: =E17*Inputs!$C$8/12 -> 0 | J17: =SUM(G17:I17) -> 3385.4167 | K17: =J17*Inputs!$C$16 -> 677.08333 | L17: =Inputs!$C$17 -> 2625 | M17: =J17-K17-L17 -> 83.333333 | N17: =N16+M17 -> -15166.667 | O17: =IF(J17=0,"",(J17-K17)/J17) -> 0.8 | P17: =IF(Actuals_Monthly!B17="","",Actuals_Monthly!B17) | Q17: =IF(OR(Actuals_Monthly!B17="",Actuals_Monthly!C17="",Actuals_Monthly!D17=""),"",Actuals_Monthly!B17-Actuals_Monthly!C17-Actuals_Monthly!D17) | R17: =IF(P17="","",P17-J17) | S17: =IF(Q17="","",Q17-M17) | T17: =IF(P17="","أدخل الفعلي",IF(R17>=0,"فوق الخطة","دون الخطة")) -> أدخل الفعلي | U17: =IF(N17>=Inputs!$C$5,1,0) -> 0
... A28: 24 | B28: ="Q"&ROUNDUP(A28/3,0) -> Q8 | C28: =C27*(1-Inputs!$C$15)+Inputs!$C$12 -> 12 | D28: =D27*(1-Inputs!$C$15)+Inputs!$C$13 -> 6 | E28: =E27*(1-Inputs!$C$15)+Inputs!$C$14 -> 0 | F28: =SUM(C28:E28) -> 18 | G28: =C28*Inputs!$C$6/12 -> 2500 | H28: =D28*Inputs!$C$7/12 -> 3750 | I28: =E28*Inputs!$C$8/12 -> 0 | J28: =SUM(G28:I28) -> 6250 | K28: =J28*Inputs!$C$16 -> 1250 | L28: =Inputs!$C$17 -> 2625 | M28: =J28-K28-L28 -> 2375 | N28: =N27+M28 -> -500 | O28: =IF(J28=0,"",(J28-K28)/J28) -> 0.8 | P28: =IF(Actuals_Monthly!B28="","",Actuals_Monthly!B28) | Q28: =IF(OR(Actuals_Monthly!B28="",Actuals_Monthly!C28="",Actuals_Monthly!D28=""),"",Actuals_Monthly!B28-Actuals_Monthly!C28-Actuals_Monthly!D28) | R28: =IF(P28="","",P28-J28) | S28: =IF(Q28="","",Q28-M28) | T28: =IF(P28="","أدخل الفعلي",IF(R28>=0,"فوق الخطة","دون الخطة")) -> أدخل الفعلي | U28: =IF(N28>=Inputs!$C$5,1,0) -> 0

Sheet Dashboard
A1: SAEIS | لوحة المؤشرات المالية والتنفيذية
A2: مؤشرات الخطة الحالية، مع حقول مقارنة الفعلي عند إدخال البيانات. الأرقام الحالية سيناريو تخطيطي قابل للتعديل.
B4: طلب التمويل | C4: =Inputs!$C$5 -> 26500 | E4: الإيراد المخطط في الشهر 12 | F4: =Monthly_Model!J16 -> 3125 | H4: الربح التشغيلي في الشهر 12 | I4: =Monthly_Model!M16 -> -125 | K4: هامش المساهمة | L4: =Monthly_Model!O16 -> 0.8
B8: نقطة التعادل الشهرية (ديناميكية) | C8: =IFERROR(Inputs!$C$17/Monthly_Model!$O$16,"") -> 3281.25 | E8: عدد العملاء عند التعادل | F8: =IFERROR(C8/(Monthly_Model!J16/Monthly_Model!F16),"") -> 9.45 | H8: فترة استرداد الاستثمار | I8: =IFERROR(INDEX(Monthly_Model!A5:A28,MATCH(1,Monthly_Model!U5:U28,0)),"غير محققة") -> غير محققة | K8: التدفق التشغيلي التراكمي في الشهر 24 | L8: =Monthly_Model!N28 -> -500
B12: الميزانية مقابل الفعلي | H12: أهداف الأثر من العرض
B13: البند | C13: المخطط | D13: الفعلي | E13: الانحراف | F13: الحالة | H13: المؤشر | I13: الهدف | J13: الفعلي | K13: الفجوة
B14: =Budget_Variance!A5 -> بناء المنتج والنسخة التجريبية | C14: =Budget_Variance!B5 -> 11925 | D14: =Budget_Variance!C5 -> 0 | E14: =Budget_Variance!D5 | F14: =Budget_Variance!F5 -> أدخل الفعلي | H14: دقة اكتشاف الأخطاء | I14: =Inputs!C19 -> 0.9 | K14: =IF(J14="","",J14-I14)
B15: =Budget_Variance!A6 -> التكامل والأمان والامتثال التقني | C15: =Budget_Variance!B6 -> 6625 | D15: =Budget_Variance!C6 -> 0 | E15: =Budget_Variance!D6 | F15: =Budget_Variance!F6 -> أدخل الفعلي | H15: خفض وقت التدقيق | I15: =Inputs!C20 -> 0.6 | K15: =IF(J15="","",J15-I15)
B16: =Budget_Variance!A7 -> إثبات السوق وتجربة العملاء | C16: =Budget_Variance!B7 -> 5300 | D16: =Budget_Variance!C7 -> 0 | E16: =Budget_Variance!D7 | F16: =Budget_Variance!F7 -> أدخل الفعلي
B17: =Budget_Variance!A8 -> التشغيل والامتثال الإداري | C17: =Budget_Variance!B8 -> 2650 | D17: =Budget_Variance!C8 -> 0 | E17: =Budget_Variance!D8 | F17: =Budget_Variance!F8 -> أدخل الفعلي
B20: قراءة سريعة للممول
B21: المعايرة الحالية تستخدم تكلفة ثابتة شهرية مستهدفة قدرها 2,625 دولارًا؛ لذلك ينخفض عجز الشهر 12 إلى 125 دولارًا عند إيراد 3,125 دولار وهامش مساهمة 80%. يُعرض التدفق التراكمي كتدفق تشغيلي، بينما التمويل الأولي يعامل كمصدر تمويل لا كمصروف تشغيلي.

Sheet PowerBI_Export
A1: Month | B1: Quarter | C1: Basic Clients Plan | D1: Professional Clients Plan | E1: Enterprise Clients Plan | F1: Total Clients Plan | G1: Basic Revenue Plan | H1: Professional Revenue Plan | I1: Enterprise Revenue Plan | J1: Total Revenue Plan | K1: Variable Cost Plan | L1: Fixed Opex Plan | M1: Operating Profit Plan | N1: Cumulative Operating Cash Plan | O1: Contribution Margin Plan | P1: Actual Revenue | Q1: Actual Variable Cost | R1: Actual Fixed Opex | S1: Actual Operating Profit | T1: Revenue Variance | U1: Profit Variance | V1: Budget Status | W1: Target Error Detection | X1: Target Audit Time Reduction
A2: 1 | B2: Q1 | C2: 0.5 | D2: 0.25 | E2: 0 | F2: 0.75 | G2: 104.16667 | H2: 156.25 | I2: 0 | J2: 260.41667 | K2: 52.083333 | L2: 4500 | M2: -4291.6667 | N2: -30791.667 | O2: 0.8 | W2: 0.9 | X2: 0.6
A3: 2 | B3: Q1 | C3: 1 | D3: 0.5 | E3: 0 | F3: 1.5 | G3: 208.33333 | H3: 312.5 | I3: 0 | J3: 520.83333 | K3: 104.16667 | L3: 4500 | M3: -4083.3333 | N3: -34875 | O3: 0.8 | W3: 0.9 | X3: 0.6
A4: 3 | B4: Q1 | C4: 1.5 | D4: 0.75 | E4: 0 | F4: 2.25 | G4: 312.5 | H4: 468.75 | I4: 0 | J4: 781.25 | K4: 156.25 | L4: 4500 | M4: -3875 | N4: -38750 | O4: 0.8 | W4: 0.9 | X4: 0.6
A5: 4 | B5: Q2 | C5: 2 | D5: 1 | E5: 0 | F5: 3 | G5: 416.66667 | H5: 625 | I5: 0 | J5: 1041.6667 | K5: 208.33333 | L5: 4500 | M5: -3666.6667 | N5: -42416.667 | O5: 0.8 | W5: 0.9 | X5: 0.6
A6: 5 | B6: Q2 | C6: 2.5 | D6: 1.25 | E6: 0 | F6: 3.75 | G6: 520.83333 | H6: 781.25 | I6: 0 | J6: 1302.0833 | K6: 260.41667 | L6: 4500 | M6: -3458.3333 | N6: -45875 | O6: 0.8 | W6: 0.9 | X6: 0.6
A7: 6 | B7: Q2 | C7: 3 | D7: 1.5 | E7: 0 | F7: 4.5 | G7: 625 | H7: 937.5 | I7: 0 | J7: 1562.5 | K7: 312.5 | L7: 4500 | M7: -3250 | N7: -49125 | O7: 0.8 | W7: 0.9 | X7: 0.6
A8: 7 | B8: Q3 | C8: 3.5 | D8: 1.75 | E8: 0 | F8: 5.25 | G8: 729.16667 | H8: 1093.75 | I8: 0 | J8: 1822.9167 | K8: 364.58333 | L8: 4500 | M8: -3041.6667 | N8: -52166.667 | O8: 0.8 | W8: 0.9 | X8: 0.6
A9: 8 | B9: Q3 | C9: 4 | D9: 2 | E9: 0 | F9: 6 | G9: 833.33333 | H9: 1250 | I9: 0 | J9: 2083.3333 | K9: 416.66667 | L9: 4500 | M9: -2833.3333 | N9: -55000 | O9: 0.8 | W9: 0.9 | X9: 0.6
A10: 9 | B10: Q3 | C10: 4.5 | D10: 2.25 | E10: 0 | F10: 6.75 | G10: 937.5 | H10: 1406.25 | I10: 0 | J10: 2343.75 | K10: 468.75 | L10: 4500 | M10: -2625 | N10: -57625 | O10: 0.8 | W10: 0.9 | X10: 0.6
A11: 10 | B11: Q4 | C11: 5 | D11: 2.5 | E11: 0 | F11: 7.5 | G11: 1041.6667 | H11: 1562.5 | I11: 0 | J11: 2604.1667 | K11: 520.83333 | L11: 4500 | M11: -2416.6667 | N11: -60041.667 | O11: 0.8 | W11: 0.9 | X11: 0.6
A12: 11 | B12: Q4 | C12: 5.5 | D12: 2.75 | E12: 0 | F12: 8.25 | G12: 1145.8333 | H12: 1718.75 | I12: 0 | J12: 2864.5833 | K12: 572.91667 | L12: 4500 | M12: -2208.3333 | N12: -62250 | O12: 0.8 | W12: 0.9 | X12: 0.6
A13: 12 | B13: Q4 | C13: 6 | D13: 3 | E13: 0 | F13: 9 | G13: 1250 | H13: 1875 | I13: 0 | J13: 3125 | K13: 625 | L13: 4500 | M13: -2000 | N13: -64250 | O13: 0.8 | W13: 0.9 | X13: 0.6
... A25: 24 | B25: Q8 | C25: 12 | D25: 6 | E25: 0 | F25: 18 | G25: 2500 | H25: 3750 | I25: 0 | J25: 6250 | K25: 1250 | L25: 4500 | M25: 500 | N25: -72000 | O25: 0.8 | W25: 0.9 | X25: 0.6

Sheet Sensitivity
A1: SAEIS | تحليل الحساسية
A2: اختبر تأثير أسعار الباقات والتكلفة المتغيرة وسرعة اكتساب العملاء على الربحية ونقطة التعادل.
A4: السيناريو | B4: سعر أساسي سنوي | C4: سعر احترافي سنوي | D4: عملاء أساسيون جدد/شهر | E4: عملاء احترافيون جدد/شهر | F4: تكلفة متغيرة % | G4: نقطة التعادل الشهرية | H4: فترة الاسترداد
A5: محافظ | B5: 2200 | C5: 6500 | D5: 0.25 | E5: 0.1 | F5: 0.3 | G5: =Inputs!$C$17/(1-F5) -> 3750 | H5: يرتبط بالحالة التشغيلية في النموذج الأساسي
A6: أساسي | B6: 2500 | C6: 7500 | D6: 0.5 | E6: 0.3 | F6: 0.2 | G6: =Inputs!$C$17/(1-F6) -> 3281.25 | H6: يرتبط بالحالة التشغيلية في النموذج الأساسي
A7: متفائل | B7: 2800 | C7: 8500 | D7: 0.75 | E7: 0.4 | F7: 0.15 | G7: =Inputs!$C$17/(1-F7) -> 3088.2353 | H7: يرتبط بالحالة التشغيلية في النموذج الأساسي

Sheet Three_Year_Forecast
A1: SAEIS | توقع الإيرادات والأرباح لثلاث سنوات
A2: سيناريو تخطيطي: الربحية تربط التكاليف الثابتة بخلية Inputs، والرصد النقدي يبدأ بتمويل المرحلة ثم يتغير بالربح التشغيلي.
A4: السيناريو | B4: الشهر | C4: السنة | D4: العملاء الأساسيون | E4: العملاء الاحترافيون | F4: إجمالي العملاء | G4: الإيراد | H4: التكلفة المتغيرة | I4: الربح التشغيلي | J4: الرصيد النقدي التراكمي بعد التمويل
A5: محافظ | B5: 1 | C5: 1 | D5: =Inputs!$C$9*(1-Inputs!$C$15)+Sensitivity!$D$5 -> 0.25 | E5: =Inputs!$C$10*(1-Inputs!$C$15)+Sensitivity!$E$5 -> 0.1 | F5: =D5+E5 -> 0.35 | G5: =D5*Sensitivity!$B$5/12+E5*Sensitivity!$C$5/12 -> 100 | H5: =G5*Sensitivity!$F$5 -> 30 | I5: =G5-H5-Inputs!$C$17 -> -2555 | J5: =Inputs!$C$5+I5 -> 23945
A6: محافظ | B6: 2 | C6: 1 | D6: =D5*(1-Inputs!$C$15)+Sensitivity!$D$5 -> 0.5 | E6: =E5*(1-Inputs!$C$15)+Sensitivity!$E$5 -> 0.2 | F6: =D6+E6 -> 0.7 | G6: =D6*Sensitivity!$B$5/12+E6*Sensitivity!$C$5/12 -> 200 | H6: =G6*Sensitivity!$F$5 -> 60 | I6: =G6-H6-Inputs!$C$17 -> -2485 | J6: =J5+I6 -> 21460
A7: محافظ | B7: 3 | C7: 1 | D7: =D6*(1-Inputs!$C$15)+Sensitivity!$D$5 -> 0.75 | E7: =E6*(1-Inputs!$C$15)+Sensitivity!$E$5 -> 0.3 | F7: =D7+E7 -> 1.05 | G7: =D7*Sensitivity!$B$5/12+E7*Sensitivity!$C$5/12 -> 300 | H7: =G7*Sensitivity!$F$5 -> 90 | I7: =G7-H7-Inputs!$C$17 -> -2415 | J7: =J6+I7 -> 19045
A8: محافظ | B8: 4 | C8: 1 | D8: =D7*(1-Inputs!$C$15)+Sensitivity!$D$5 -> 1 | E8: =E7*(1-Inputs!$C$15)+Sensitivity!$E$5 -> 0.4 | F8: =D8+E8 -> 1.4 | G8: =D8*Sensitivity!$B$5/12+E8*Sensitivity!$C$5/12 -> 400 | H8: =G8*Sensitivity!$F$5 -> 120 | I8: =G8-H8-Inputs!$C$17 -> -2345 | J8: =J7+I8 -> 16700
A9: محافظ | B9: 5 | C9: 1 | D9: =D8*(1-Inputs!$C$15)+Sensitivity!$D$5 -> 1.25 | E9: =E8*(1-Inputs!$C$15)+Sensitivity!$E$5 -> 0.5 | F9: =D9+E9 -> 1.75 | G9: =D9*Sensitivity!$B$5/12+E9*Sensitivity!$C$5/12 -> 500 | H9: =G9*Sensitivity!$F$5 -> 150 | I9: =G9-H9-Inputs!$C$17 -> -2275 | J9: =J8+I9 -> 14425
A10: محافظ | B10: 6 | C10: 1 | D10: =D9*(1-Inputs!$C$15)+Sensitivity!$D$5 -> 1.5 | E10: =E9*(1-Inputs!$C$15)+Sensitivity!$E$5 -> 0.6 | F10: =D10+E10 -> 2.1 | G10: =D10*Sensitivity!$B$5/12+E10*Sensitivity!$C$5/12 -> 600 | H10: =G10*Sensitivity!$F$5 -> 180 | I10: =G10-H10-Inputs!$C$17 -> -2205 | J10: =J9+I10 -> 12220
A11: محافظ | B11: 7 | C11: 1 | D11: =D10*(1-Inputs!$C$15)+Sensitivity!$D$5 -> 1.75 | E11: =E10*(1-Inputs!$C$15)+Sensitivity!$E$5 -> 0.7 | F11: =D11+E11 -> 2.45 | G11: =D11*Sensitivity!$B$5/12+E11*Sensitivity!$C$5/12 -> 700 | H11: =G11*Sensitivity!$F$5 -> 210 | I11: =G11-H11-Inputs!$C$17 -> -2135 | J11: =J10+I11 -> 10085
A12: محافظ | B12: 8 | C12: 1 | D12: =D11*(1-Inputs!$C$15)+Sensitivity!$D$5 -> 2 | E12: =E11*(1-Inputs!$C$15)+Sensitivity!$E$5 -> 0.8 | F12: =D12+E12 -> 2.8 | G12: =D12*Sensitivity!$B$5/12+E12*Sensitivity!$C$5/12 -> 800 | H12: =G12*Sensitivity!$F$5 -> 240 | I12: =G12-H12-Inputs!$C$17 -> -2065 | J12: =J11+I12 -> 8020
A13: محافظ | B13: 9 | C13: 1 | D13: =D12*(1-Inputs!$C$15)+Sensitivity!$D$5 -> 2.25 | E13: =E12*(1-Inputs!$C$15)+Sensitivity!$E$5 -> 0.9 | F13: =D13+E13 -> 3.15 | G13: =D13*Sensitivity!$B$5/12+E13*Sensitivity!$C$5/12 -> 900 | H13: =G13*Sensitivity!$F$5 -> 270 | I13: =G13-H13-Inputs!$C$17 -> -1995 | J13: =J12+I13 -> 6025
A14: محافظ | B14: 10 | C14: 1 | D14: =D13*(1-Inputs!$C$15)+Sensitivity!$D$5 -> 2.5 | E14: =E13*(1-Inputs!$C$15)+Sensitivity!$E$5 -> 1 | F14: =D14+E14 -> 3.5 | G14: =D14*Sensitivity!$B$5/12+E14*Sensitivity!$C$5/12 -> 1000 | H14: =G14*Sensitivity!$F$5 -> 300 | I14: =G14-H14-Inputs!$C$17 -> -1925 | J14: =J13+I14 -> 4100
A15: محافظ | B15: 11 | C15: 1 | D15: =D14*(1-Inputs!$C$15)+Sensitivity!$D$5 -> 2.75 | E15: =E14*(1-Inputs!$C$15)+Sensitivity!$E$5 -> 1.1 | F15: =D15+E15 -> 3.85 | G15: =D15*Sensitivity!$B$5/12+E15*Sensitivity!$C$5/12 -> 1100 | H15: =G15*Sensitivity!$F$5 -> 330 | I15: =G15-H15-Inputs!$C$17 -> -1855 | J15: =J14+I15 -> 2245
A16: محافظ | B16: 12 | C16: 1 | D16: =D15*(1-Inputs!$C$15)+Sensitivity!$D$5 -> 3 | E16: =E15*(1-Inputs!$C$15)+Sensitivity!$E$5 -> 1.2 | F16: =D16+E16 -> 4.2 | G16: =D16*Sensitivity!$B$5/12+E16*Sensitivity!$C$5/12 -> 1200 | H16: =G16*Sensitivity!$F$5 -> 360 | I16: =G16-H16-Inputs!$C$17 -> -1785 | J16: =J15+I16 -> 460
A17: محافظ | B17: 13 | C17: 2 | D17: =D16*(1-Inputs!$C$15)+Sensitivity!$D$5 -> 3.25 | E17: =E16*(1-Inputs!$C$15)+Sensitivity!$E$5 -> 1.3 | F17: =D17+E17 -> 4.55 | G17: =D17*Sensitivity!$B$5/12+E17*Sensitivity!$C$5/12 -> 1300 | H17: =G17*Sensitivity!$F$5 -> 390 | I17: =G17-H17-Inputs!$C$17 -> -1715 | J17: =J16+I17 -> -1255
... A40: محافظ | B40: 36 | C40: 3 | D40: =D39*(1-Inputs!$C$15)+Sensitivity!$D$5 -> 9 | E40: =E39*(1-Inputs!$C$15)+Sensitivity!$E$5 -> 3.6 | F40: =D40+E40 -> 12.6 | G40: =D40*Sensitivity!$B$5/12+E40*Sensitivity!$C$5/12 -> 3600 | H40: =G40*Sensitivity!$F$5 -> 1080 | I40: =G40-H40-Inputs!$C$17 -> -105 | J40: =J39+I40 -> -21380
A41: أساسي | B41: 1 | C41: 1 | D41: =Inputs!$C$9*(1-Inputs!$C$15)+Sensitivity!$D$6 -> 0.5 | E41: =Inputs!$C$10*(1-Inputs!$C$15)+Sensitivity!$E$6 -> 0.3 | F41: =D41+E41 -> 0.8 | G41: =D41*Sensitivity!$B$6/12+E41*Sensitivity!$C$6/12 -> 291.66667 | H41: =G41*Sensitivity!$F$6 -> 58.333333 | I41: =G41-H41-Inputs!$C$17 -> -2391.6667 | J41: =Inputs!$C$5+I41 -> 24108.333
A42: أساسي | B42: 2 | C42: 1 | D42: =D41*(1-Inputs!$C$15)+Sensitivity!$D$6 -> 1 | E42: =E41*(1-Inputs!$C$15)+Sensitivity!$E$6 -> 0.6 | F42: =D42+E42 -> 1.6 | G42: =D42*Sensitivity!$B$6/12+E42*Sensitivity!$C$6/12 -> 583.33333 | H42: =G42*Sensitivity!$F$6 -> 116.66667 | I42: =G42-H42-Inputs!$C$17 -> -2158.3333 | J42: =J41+I42 -> 21950
A43: أساسي | B43: 3 | C43: 1 | D43: =D42*(1-Inputs!$C$15)+Sensitivity!$D$6 -> 1.5 | E43: =E42*(1-Inputs!$C$15)+Sensitivity!$E$6 -> 0.9 | F43: =D43+E43 -> 2.4 | G43: =D43*Sensitivity!$B$6/12+E43*Sensitivity!$C$6/12 -> 875 | H43: =G43*Sensitivity!$F$6 -> 175 | I43: =G43-H43-Inputs!$C$17 -> -1925 | J43: =J42+I43 -> 20025
A44: أساسي | B44: 4 | C44: 1 | D44: =D43*(1-Inputs!$C$15)+Sensitivity!$D$6 -> 2 | E44: =E43*(1-Inputs!$C$15)+Sensitivity!$E$6 -> 1.2 | F44: =D44+E44 -> 3.2 | G44: =D44*Sensitivity!$B$6/12+E44*Sensitivity!$C$6/12 -> 1166.6667 | H44: =G44*Sensitivity!$F$6 -> 233.33333 | I44: =G44-H44-Inputs!$C$17 -> -1691.6667 | J44: =J43+I44 -> 18333.333
A45: أساسي | B45: 5 | C45: 1 | D45: =D44*(1-Inputs!$C$15)+Sensitivity!$D$6 -> 2.5 | E45: =E44*(1-Inputs!$C$15)+Sensitivity!$E$6 -> 1.5 | F45: =D45+E45 -> 4 | G45: =D45*Sensitivity!$B$6/12+E45*Sensitivity!$C$6/12 -> 1458.3333 | H45: =G45*Sensitivity!$F$6 -> 291.66667 | I45: =G45-H45-Inputs!$C$17 -> -1458.3333 | J45: =J44+I45 -> 16875
A46: أساسي | B46: 6 | C46: 1 | D46: =D45*(1-Inputs!$C$15)+Sensitivity!$D$6 -> 3 | E46: =E45*(1-Inputs!$C$15)+Sensitivity!$E$6 -> 1.8 | F46: =D46+E46 -> 4.8 | G46: =D46*Sensitivity!$B$6/12+E46*Sensitivity!$C$6/12 -> 1750 | H46: =G46*Sensitivity!$F$6 -> 350 | I46: =G46-H46-Inputs!$C$17 -> -1225 | J46: =J45+I46 -> 15650
A47: أساسي | B47: 7 | C47: 1 | D47: =D46*(1-Inputs!$C$15)+Sensitivity!$D$6 -> 3.5 | E47: =E46*(1-Inputs!$C$15)+Sensitivity!$E$6 -> 2.1 | F47: =D47+E47 -> 5.6 | G47: =D47*Sensitivity!$B$6/12+E47*Sensitivity!$C$6/12 -> 2041.6667 | H47: =G47*Sensitivity!$F$6 -> 408.33333 | I47: =G47-H47-Inputs!$C$17 -> -991.66667 | J47: =J46+I47 -> 14658.333
A48: أساسي | B48: 8 | C48: 1 | D48: =D47*(1-Inputs!$C$15)+Sensitivity!$D$6 -> 4 | E48: =E47*(1-Inputs!$C$15)+Sensitivity!$E$6 -> 2.4 | F48: =D48+E48 -> 6.4 | G48: =D48*Sensitivity!$B$6/12+E48*Sensitivity!$C$6/12 -> 2333.3333 | H48: =G48*Sensitivity!$F$6 -> 466.66667 | I48: =G48-H48-Inputs!$C$17 -> -758.33333 | J48: =J47+I48 -> 13900
A49: أساسي | B49: 9 | C49: 1 | D49: =D48*(1-Inputs!$C$15)+Sensitivity!$D$6 -> 4.5 | E49: =E48*(1-Inputs!$C$15)+Sensitivity!$E$6 -> 2.7 | F49: =D49+E49 -> 7.2 | G49: =D49*Sensitivity!$B$6/12+E49*Sensitivity!$C$6/12 -> 2625 | H49: =G49*Sensitivity!$F$6 -> 525 | I49: =G49-H49-Inputs!$C$17 -> -525 | J49: =J48+I49 -> 13375
A50: أساسي | B50: 10 | C50: 1 | D50: =D49*(1-Inputs!$C$15)+Sensitivity!$D$6 -> 5 | E50: =E49*(1-Inputs!$C$15)+Sensitivity!$E$6 -> 3 | F50: =D50+E50 -> 8 | G50: =D50*Sensitivity!$B$6/12+E50*Sensitivity!$C$6/12 -> 2916.6667 | H50: =G50*Sensitivity!$F$6 -> 583.33333 | I50: =G50-H50-Inputs!$C$17 -> -291.66667 | J50: =J49+I50 -> 13083.333
A51: أساسي | B51: 11 | C51: 1 | D51: =D50*(1-Inputs!$C$15)+Sensitivity!$D$6 -> 5.5 | E51: =E50*(1-Inputs!$C$15)+Sensitivity!$E$6 -> 3.3 | F51: =D51+E51 -> 8.8 | G51: =D51*Sensitivity!$B$6/12+E51*Sensitivity!$C$6/12 -> 3208.3333 | H51: =G51*Sensitivity!$F$6 -> 641.66667 | I51: =G51-H51-Inputs!$C$17 -> -58.333333 | J51: =J50+I51 -> 13025
A52: أساسي | B52: 12 | C52: 1 | D52: =D51*(1-Inputs!$C$15)+Sensitivity!$D$6 -> 6 | E52: =E51*(1-Inputs!$C$15)+Sensitivity!$E$6 -> 3.6 | F52: =D52+E52 -> 9.6 | G52: =D52*Sensitivity!$B$6/12+E52*Sensitivity!$C$6/12 -> 3500 | H52: =G52*Sensitivity!$F$6 -> 700 | I52: =G52-H52-Inputs!$C$17 -> 175 | J52: =J51+I52 -> 13200
A53: أساسي | B53: 13 | C53: 2 | D53: =D52*(1-Inputs!$C$15)+Sensitivity!$D$6 -> 6.5 | E53: =E52*(1-Inputs!$C$15)+Sensitivity!$E$6 -> 3.9 | F53: =D53+E53 -> 10.4 | G53: =D53*Sensitivity!$B$6/12+E53*Sensitivity!$C$6/12 -> 3791.6667 | H53: =G53*Sensitivity!$F$6 -> 758.33333 | I53: =G53-H53-Inputs!$C$17 -> 408.33333 | J53: =J52+I53 -> 13608.333
... A76: أساسي | B76: 36 | C76: 3 | D76: =D75*(1-Inputs!$C$15)+Sensitivity!$D$6 -> 18 | E76: =E75*(1-Inputs!$C$15)+Sensitivity!$E$6 -> 10.8 | F76: =D76+E76 -> 28.8 | G76: =D76*Sensitivity!$B$6/12+E76*Sensitivity!$C$6/12 -> 10500 | H76: =G76*Sensitivity!$F$6 -> 2100 | I76: =G76-H76-Inputs!$C$17 -> 5775 | J76: =J75+I76 -> 87400
A77: متفائل | B77: 1 | C77: 1 | D77: =Inputs!$C$9*(1-Inputs!$C$15)+Sensitivity!$D$7 -> 0.75 | E77: =Inputs!$C$10*(1-Inputs!$C$15)+Sensitivity!$E$7 -> 0.4 | F77: =D77+E77 -> 1.15 | G77: =D77*Sensitivity!$B$7/12+E77*Sensitivity!$C$7/12 -> 458.33333 | H77: =G77*Sensitivity!$F$7 -> 68.75 | I77: =G77-H77-Inputs!$C$17 -> -2235.4167 | J77: =Inputs!$C$5+I77 -> 24264.583
A78: متفائل | B78: 2 | C78: 1 | D78: =D77*(1-Inputs!$C$15)+Sensitivity!$D$7 -> 1.5 | E78: =E77*(1-Inputs!$C$15)+Sensitivity!$E$7 -> 0.8 | F78: =D78+E78 -> 2.3 | G78: =D78*Sensitivity!$B$7/12+E78*Sensitivity!$C$7/12 -> 916.66667 | H78: =G78*Sensitivity!$F$7 -> 137.5 | I78: =G78-H78-Inputs!$C$17 -> -1845.8333 | J78: =J77+I78 -> 22418.75
A79: متفائل | B79: 3 | C79: 1 | D79: =D78*(1-Inputs!$C$15)+Sensitivity!$D$7 -> 2.25 | E79: =E78*(1-Inputs!$C$15)+Sensitivity!$E$7 -> 1.2 | F79: =D79+E79 -> 3.45 | G79: =D79*Sensitivity!$B$7/12+E79*Sensitivity!$C$7/12 -> 1375 | H79: =G79*Sensitivity!$F$7 -> 206.25 | I79: =G79-H79-Inputs!$C$17 -> -1456.25 | J79: =J78+I79 -> 20962.5
A80: متفائل | B80: 4 | C80: 1 | D80: =D79*(1-Inputs!$C$15)+Sensitivity!$D$7 -> 3 | E80: =E79*(1-Inputs!$C$15)+Sensitivity!$E$7 -> 1.6 | F80: =D80+E80 -> 4.6 | G80: =D80*Sensitivity!$B$7/12+E80*Sensitivity!$C$7/12 -> 1833.3333 | H80: =G80*Sensitivity!$F$7 -> 275 | I80: =G80-H80-Inputs!$C$17 -> -1066.6667 | J80: =J79+I80 -> 19895.833
A81: متفائل | B81: 5 | C81: 1 | D81: =D80*(1-Inputs!$C$15)+Sensitivity!$D$7 -> 3.75 | E81: =E80*(1-Inputs!$C$15)+Sensitivity!$E$7 -> 2 | F81: =D81+E81 -> 5.75 | G81: =D81*Sensitivity!$B$7/12+E81*Sensitivity!$C$7/12 -> 2291.6667 | H81: =G81*Sensitivity!$F$7 -> 343.75 | I81: =G81-H81-Inputs!$C$17 -> -677.08333 | J81: =J80+I81 -> 19218.75
A82: متفائل | B82: 6 | C82: 1 | D82: =D81*(1-Inputs!$C$15)+Sensitivity!$D$7 -> 4.5 | E82: =E81*(1-Inputs!$C$15)+Sensitivity!$E$7 -> 2.4 | F82: =D82+E82 -> 6.9 | G82: =D82*Sensitivity!$B$7/12+E82*Sensitivity!$C$7/12 -> 2750 | H82: =G82*Sensitivity!$F$7 -> 412.5 | I82: =G82-H82-Inputs!$C$17 -> -287.5 | J82: =J81+I82 -> 18931.25
A83: متفائل | B83: 7 | C83: 1 | D83: =D82*(1-Inputs!$C$15)+Sensitivity!$D$7 -> 5.25 | E83: =E82*(1-Inputs!$C$15)+Sensitivity!$E$7 -> 2.8 | F83: =D83+E83 -> 8.05 | G83: =D83*Sensitivity!$B$7/12+E83*Sensitivity!$C$7/12 -> 3208.3333 | H83: =G83*Sensitivity!$F$7 -> 481.25 | I83: =G83-H83-Inputs!$C$17 -> 102.08333 | J83: =J82+I83 -> 19033.333
A84: متفائل | B84: 8 | C84: 1 | D84: =D83*(1-Inputs!$C$15)+Sensitivity!$D$7 -> 6 | E84: =E83*(1-Inputs!$C$15)+Sensitivity!$E$7 -> 3.2 | F84: =D84+E84 -> 9.2 | G84: =D84*Sensitivity!$B$7/12+E84*Sensitivity!$C$7/12 -> 3666.6667 | H84: =G84*Sensitivity!$F$7 -> 550 | I84: =G84-H84-Inputs!$C$17 -> 491.66667 | J84: =J83+I84 -> 19525
A85: متفائل | B85: 9 | C85: 1 | D85: =D84*(1-Inputs!$C$15)+Sensitivity!$D$7 -> 6.75 | E85: =E84*(1-Inputs!$C$15)+Sensitivity!$E$7 -> 3.6 | F85: =D85+E85 -> 10.35 | G85: =D85*Sensitivity!$B$7/12+E85*Sensitivity!$C$7/12 -> 4125 | H85: =G85*Sensitivity!$F$7 -> 618.75 | I85: =G85-H85-Inputs!$C$17 -> 881.25 | J85: =J84+I85 -> 20406.25
...

Sheet Sensitivity_3Y
A1: SAEIS | تحليل حساسية إيرادات السنة الثالثة
A2: التأثير المشترك لتغير السعر وسرعة اكتساب العملاء، مع ثبات باقي الافتراضات التشغيلية.
A3: خريطة الألوان: الأحمر = نطاق إيراد أقل، والعنبر = متوسط، والأخضر = نطاق إيراد أعلى. القيم تخطيطية وقابلة للتعديل.
A4: مضاعف نمو العملاء / مضاعف السعر | B4: 0.8x السعر | C4: 1.0x السعر | D4: 1.2x السعر
A5: 0.5x نمو العملاء | B5: 42700 | C5: 53375 | D5: 64050
A6: 1.0x نمو العملاء | B6: 85400 | C6: 106750 | D6: 128100
A7: 1.5x نمو العملاء | B7: 128100 | C7: 160125 | D7: 192150
A10: السيناريو الأساسي المرتبط
A11: عملاء أساسيون جدد/شهر | B11: =Sensitivity!D6 -> 0.5 | C11: عملاء احترافيون جدد/شهر | D11: =Sensitivity!E6 -> 0.3
A13: تعليمات الاستخدام: تعتمد ورقة Three_Year_Forecast على قيم صف «أساسي» في تبويب Sensitivity. عدّل هذا الصف لتحديث خط الإيرادات والأرباح والرصد النقدي تلقائيًا.
